==============================================
Hostname: fg4
Job ID: 29143360
Node: fg4
/home/ramin.kahidi/software/miniconda3/envs/pytorch/lib/python3.7/site-packages/torchvision/io/image.py:13: UserWarning: Failed to load image Python extension: /home/ramin.kahidi/software/miniconda3/envs/pytorch/lib/python3.7/site-packages/torchvision/image.so: undefined symbol: _ZN5torch3jit17parseSchemaOrNameERKNSt7__cxx1112basic_stringIcSt11char_traitsIcESaIcEEE
  warn(f"Failed to load image Python extension: {e}")
Traceback (most recent call last):
  File "DAFTTrain.py", line 266, in <module>
    main(MRI_dir, tabular_dir)
  File "DAFTTrain.py", line 131, in main
    for batch_data in train_loader:
  File "/home/ramin.kahidi/software/miniconda3/envs/pytorch/lib/python3.7/site-packages/torch/utils/data/dataloader.py", line 628, in __next__
    data = self._next_data()
  File "/home/ramin.kahidi/software/miniconda3/envs/pytorch/lib/python3.7/site-packages/torch/utils/data/dataloader.py", line 1333, in _next_data
    return self._process_data(data)
  File "/home/ramin.kahidi/software/miniconda3/envs/pytorch/lib/python3.7/site-packages/torch/utils/data/dataloader.py", line 1359, in _process_data
    data.reraise()
  File "/home/ramin.kahidi/software/miniconda3/envs/pytorch/lib/python3.7/site-packages/torch/_utils.py", line 543, in reraise
    raise exception
KeyError: Caught KeyError in DataLoader worker process 0.
Original Traceback (most recent call last):
  File "/home/ramin.kahidi/software/miniconda3/envs/pytorch/lib/python3.7/site-packages/pandas/core/indexes/base.py", line 3361, in get_loc
    return self._engine.get_loc(casted_key)
  File "pandas/_libs/index.pyx", line 76, in pandas._libs.index.IndexEngine.get_loc
  File "pandas/_libs/index.pyx", line 108, in pandas._libs.index.IndexEngine.get_loc
  File "pandas/_libs/hashtable_class_helper.pxi", line 5198, in pandas._libs.hashtable.PyObjectHashTable.get_item
  File "pandas/_libs/hashtable_class_helper.pxi", line 5206, in pandas._libs.hashtable.PyObjectHashTable.get_item
KeyError: 'Tumor Progression_1.0'

The above exception was the direct cause of the following exception:

Traceback (most recent call last):
  File "/home/ramin.kahidi/software/miniconda3/envs/pytorch/lib/python3.7/site-packages/torch/utils/data/_utils/worker.py", line 302, in _worker_loop
    data = fetcher.fetch(index)
  File "/home/ramin.kahidi/software/miniconda3/envs/pytorch/lib/python3.7/site-packages/torch/utils/data/_utils/fetch.py", line 58, in fetch
    data = [self.dataset[idx] for idx in possibly_batched_index]
  File "/home/ramin.kahidi/software/miniconda3/envs/pytorch/lib/python3.7/site-packages/torch/utils/data/_utils/fetch.py", line 58, in <listcomp>
    data = [self.dataset[idx] for idx in possibly_batched_index]
  File "/home/ramin.kahidi/software/miniconda3/envs/pytorch/lib/python3.7/site-packages/torch/utils/data/dataset.py", line 295, in __getitem__
    return self.dataset[self.indices[idx]]
  File "/home/ramin.kahidi/CPSC571/DAFT_CPSC_571/customDataLoader.py", line 151, in __getitem__
    label = torch.tensor([float(tabular_row[label_column]) for label_column in label_columns])
  File "/home/ramin.kahidi/CPSC571/DAFT_CPSC_571/customDataLoader.py", line 151, in <listcomp>
    label = torch.tensor([float(tabular_row[label_column]) for label_column in label_columns])
  File "/home/ramin.kahidi/software/miniconda3/envs/pytorch/lib/python3.7/site-packages/pandas/core/series.py", line 942, in __getitem__
    return self._get_value(key)
  File "/home/ramin.kahidi/software/miniconda3/envs/pytorch/lib/python3.7/site-packages/pandas/core/series.py", line 1051, in _get_value
    loc = self.index.get_loc(label)
  File "/home/ramin.kahidi/software/miniconda3/envs/pytorch/lib/python3.7/site-packages/pandas/core/indexes/base.py", line 3363, in get_loc
    raise KeyError(key) from err
KeyError: 'Tumor Progression_1.0'

==============================================
Start: 2024-04-13 01:35:34
End: 2024-04-13 01:45:42
